Workbook

Sheet Sheet1
A1: Experimental Velocity [cm/s] | C1: Column1
A2: temperature
A3: dive_time | D3: https://sd-esweetapp.eni.com/FUSION_MATERIAL
A4: crucible
A5: id_material | D5: id_test_code
A6: density [g/m^3] | D6: crucible
A7: Ni_mol | D7: author
A8: Cr_mol | D8: id_paper
A9: Mo_mol | D9: institution
A10: Fe_mol | D10: year
A11: W_mol | D11: element_wt
A12: Co_mol | D12: id_material
A13: Mn_mol | D13: element_mol
A14: Al_mol | D14: beam_energy | E14: MeV
A15: Ti_mol | D15: dive_time
A16: Si_mol2 | D16: euf3 | E16: wt%
A17: C_mol | D17: length_a_sample
A18: Cu_mol | D18: length_b_sample
A19: Nb_mol | D19: molten_salt
A20: V_mol | D20: ms_purified
A21: P_mol | D21: radiation_exposure
A22: S_mol | D22: temperature | E22: °C
A23: B_mol | D23: test_condition
A24: Mg_mol | D24: thickness_sample
A25: Sn_mol | D25: average_normalized_corrosion_depth
A26: Zr_mol | D26: corrosion_class
A27: O_mol | D27: max_depth_selective_diss | E27: Max depth of selective Cr dissolution from SEM/EDS analyses (µm)
A28: N_mol | D28: sem_um_y
A29: Y_mol | D29: weight_loss | E29: weight change (mg cm-2) (- = mass loss)**
A30: H_mol | D30: C0_Cr
A31: Ellingham ∆G [kcal/gfw] of material (approx. With Ni-Cr-Mo-Fe-W-Co-Mn-Al-Ti potential weighted by mol%) | D31: density | E31: del materiale
A32: Ellingham ∆G [kcal/gfw] of crucible (approx. With Ni-Cr-Mo-Fe-W-Co-Mn-Al-Ti potential weighted by mol%) | D32: element_ppmw impurity pre
A33: length_a_sample | D33: note
A34: length_b_sample | D34: reliability | E34: corrosion class | F34: da verificare
A35: thickness_sample
A36: molten_salt
A37: ms_purified
A38: Residual Moisture wt.%
A39: euf3
A40: Fe_ppmw impurity pre
...

Sheet Ellingham diagram linear coeffi
K2: https://doi.org/10.1016/j.corsci.2018.08.035
K3: https://enispa.sharepoint.com/sites/Venicelaboratories-FLiNaKandFLiBecorrosion/Documenti%20condivisi/FLiNaK%20and%20FLiBe%20corrosion/2023-09-AI%20for%20Fusion%20Material(s).pdf
K4: ELLINGHAM DIAGRAM REDUCTION POTENTIAL [V] LINEAR COEFFICIENTS
K6: Element | L6: ID | M6: Linear coefficien [m] | N6: Linear intercept [q] | O6: Validity condition
K7: Ni | L7: Ni-NiF2 | M7: 2e-05 | N7: -3.073852
K8: Cr | L8: Cr_x0002_CrF2[lower] | M8: -7.9e-05 | N8: -3.881452 | O8: Lower
K9: Cr | L9: Cr_x0002_CrF3[upper] | M9: 0.000259 | N9: -3.720559 | O9: Upper
K10: Mo | L10: Mo_x0002_MoF5[lower] | M10: 0.00012 | N10: -2.518298 | O10: Lower
K11: Mo | L11: Mo_x0002_MoF6[upper] | M11: 0.000279 | N11: -2.605788 | O11: Upper
K12: Fe | L12: Fe_x0002_FeF2[lower] | M12: -0.00012 | N12: -3.416168 | O12: Lower
K13: Fe | L13: Fe_x0002_FeF3[upper] | M13: 0.00028 | N13: -3.306949 | O13: Upper
K14: W | L14: W-WF6 | M14: 0.000319 | N14: -2.897206
K15: Co | L15: Co-CoF2 | M15: -6e-05 | N15: -3.209408
K16: Mn | L16: Mn-MnF2 | M16: -2e-05 | N16: -4.273367
K17: Al | L17: Al-AlF3 | M17: 0.000459 | N17: -4.872255
K18: Ti | L18: Ti-TiF4 | M18: 0.000399 | N18: -4.120758
K19: Zr | L19: Zr-ZrF4 | M19: 0.000401 | N19: -4.66095
K20: Be | L20: Be_x0002_BeF2[FliBe] | M20: 0.000619 | N20: -5.097804 | O20: FliBe
K21: Eu3+ | L21: Eu3+- Eu2+[0.005] | M21: 0.000722 | N21: -4.67472 | O21: 0.005
K22: Eu3+ | L22: Eu3+- Eu2+[0.05] | M22: 0.000956 | N22: -4.651249 | O22: 0.05
K23: HF | L23: HF-H2 | M23: -0.00082 | N23: -3.091411
K24: K | L24: K_x0002_KF[FliNaK] | M24: 0.000741 | N24: -5.422714 | O24: FliNaK
K25: Li | L25: Li_x0002_LiF[FliBe] | M25: 0.000619 | N25: -6.025948 | O25: FliBe
K26: Li | L26: Li_x0002_LiF[FliNaK] | M26: 0.000701 | N26: -5.939593 | O26: FliNaK
K27: Li | L27: Li-LiF[LiF_x0002_CaF2] | M27: 0.000741 | N27: -5.91972 | O27: LiF-CaF2
K28: Na | L28: Na_x0002_NaF[FliNaK] | M28: 0.000661 | N28: -5.486413 | O28: FliNaK
E30: https://enispa.sharepoint.com/sites/Venicelaboratories-FLiNaKandFLiBecorrosion/Documenti%20condivisi/FLiNaK%20and%20FLiBe%20corrosion/Diagrammi%20dei%20potenziali%20di%20Ellingham%20Delta_G.pdf
E31: ELLINGHAM DIAGRAM GIBBS FREE ENERGY [kcal/gfw] DATA POINTS FOR LINEAR COEFFICIENTS | K31: ELLINGHAM DIAGRAM GIBBS FREE ENERGY [kcal/gfw] LINEAR COEFFICIENTS
AC32: ELLINGHAM DIAGRAM GIBBS FREE ENERGY [kcal/gfw] DATA POINTS FOR LINEAR COEFFICIENTS
E33: Element | F33: ID | G33: point 1 or 2 | H33: X | I33: Y | K33: Element | L33: ID | M33: Linear coefficien [m] | N33: Linear intercept [q] | O33: n
D34: 4 | E34: Si | F34: Si-SiF4 | G34: 1 | H34: 0 | I34: -185.39 | K34: Si | L34: Si-SiF4 | M34: =(I35-I34)/(H35-H34) -> 0.016836277 | N34: =(I34*H35-I35*H34)/(H35-H34) -> -185.39 | O34: 4 | AC34: Element | AD34: ID | AE34: point 1 or 2 | AF34: X | AG34: Y
G35: 2 | H35: 1683.27 | I35: -157.05 | K35: C | L35: C-CF4 | M35: =(I37-I36)/(H37-H36) -> 0.018075 | N35: =(I36*H37-I37*H36)/(H37-H36) -> -81.13 | O35: 4 | AC35: Si | AD35: Si-SiF4 | AE35: 1 | AF35: 0 | AG35: -184.65
D36: 1 | E36: C | F36: C-CF4 | G36: 1 | H36: 0 | I36: -81.13 | K36: Cu | L36: Cu-CuF2 | M36: =(I39-I38)/(H39-H38) -> 0.031766667 | N36: =(I38*H39-I39*H38)/(H39-H38) -> -127 | O36: 2 | AE36: 2 | AF36: 2400 | AG36: -142.4
G37: 2 | H37: 2400 | I37: -37.75 | K37: Nb | L37: Nb-NbF5 | M37: =(I41-I40)/(H41-H40) -> 0.021410506 | N37: =(I40*H41-I41*H40)/(H41-H40) -> -167.17521 | O37: 5 | AC37: C | AD37: C-CF4 | AE37: 1 | AF37: 0 | AG37: -81.74
D38: 2 | E38: Cu | F38: Cu-CuF2 | G38: 1 | H38: 0 | I38: -127 | K38: V | L38: V-VF3 | M38: =(I43-I42)/(H43-H42) -> 0.037427694 | N38: =(I42*H43-I43*H42)/(H43-H42) -> -189.94 | O38: 3 | AE38: 2 | AF38: 2400 | AG38: -36
G39: 2 | H39: 1200 | I39: -88.88 | K39: P | L39: P-PF3 | O39: 3 | AC39: Cu | AD39: Cu-CuF2 | AE39: 1 | AF39: 0 | AG39: -127.6
D40: 3 | E40: Nb | F40: Nb-NbF5 | G40: 1 | H40: 506.07 | I40: -156.34 | K40: S | L40: S-SF6 | M40: =(I47-I46)/(H47-H46) -> 0.033278195 | N40: =(I46*H47-I47*H46)/(H47-H46) -> -86.61 | O40: 6 | AE40: 2 | AF40: 1203.91 | AG40: -89.56
G41: 2 | H41: 2400 | I41: -115.79 | K41: B | L41: B-BF3 | M41: =(I49-I48)/(H49-H48) -> 0.0099782609 | N41: =(I48*H49-I49*H48)/(H49-H48) -> -183 | O41: 3 | AC41: Nb | AD41: Nb-NbF5 | AE41: 1 | AF41: 504.9 | AG41: -163.98
D42: 5 | E42: V | F42: V-VF3 | G42: 1 | H42: 0 | I42: -189.94 | K42: Mg | L42: Mg-MgF2 | M42: =(I51-I50)/(H51-H50) -> 0.03612228 | N42: =(I50*H51-I51*H50)/(H51-H50) -> -257.347 | O42: 2 | AE42: 2 | AF42: 2400 | AG42: -125.7
G43: 2 | H43: 1400.3 | I43: -137.53 | K43: Y | L43: Y-YF3 | M43: =(I53-I52)/(H53-H52) -> 0.034065312 | N43: =(I52*H53-I53*H52)/(H53-H52) -> -264.58 | O43: 3 | AC43: V | AD43: V-VF3 | AE43: 1 | AF43: 0 | AG43: -189.6
...

Sheet ∆G Ellingham Diagram coeff.
E4: ELLINGHAM DIAGRAM GIBBS FREE ENERGY [kcal/gfw] LINEAR COEFFICIENTS
E6: Element | F6: ID | G6: Linear coefficien [m] | H6: Linear intercept [q] | I6: n
E7: Ni | F7: Ni-NiF2 | G7: =(I56-I55)/(H56-H55) -> 0.03574835 | H7: =(I55*H56-I56*H55)/(H56-H55) -> -156.53674 | I7: 2
E8: Cr | F8: Cr-CrF3 | G8: =(I48-I47)/(H48-H47) -> 0.034303053 | H8: =(I47*H48-I48*H47)/(H48-H47) -> -183.12224 | I8: 3
E9: Mo | F9: Mo-MoF6 | G9: =(I60-I59)/(H60-H59) -> 0.019623591 | H9: =(I59*H60-I60*H59)/(H60-H59) -> -134.05365 | I9: 6
E10: Fe | F10: Fe-FeF2 | G10: =(I50-I49)/(H50-H49) -> 0.031926827 | H10: =(I49*H50-I50*H49)/(H50-H49) -> -167.09965 | I10: 2
E11: W | F11: W-WF6 | I11: 6
E12: Co | F12: Co-CoF2 | G12: =(I46-I45)/(H46-H45) -> 0.033738355 | H12: =(I45*H46-I46*H45)/(H46-H45) -> -158.01839 | I12: 2
E13: Mn | F13: Mn-MnF2 | G13: =(I58-I57)/(H58-H57) -> 0.032513859 | H13: =(I57*H58-I58*H57)/(H58-H57) -> -189.5413 | I13: 2
E14: Al | F14: Al-AlF3 | G14: =(I42-I41)/(H42-H41) -> 0.040663111 | H14: =(I41*H42-I42*H41)/(H42-H41) -> -218.83548 | I14: 3
E15: Ti | F15: Ti-TiF4 | G15: =(I66-I65)/(H66-H65) -> 0.012211537 | H15: =(I65*H66-I66*H65)/(H66-H65) -> -173.76612 | I15: 4
E16: Si | F16: Si-SiF4 | G16: =(I64-I63)/(H64-H63) -> 0.016867496 | H16: =(I63*H64-I64*H63)/(H64-H63) -> -185.44799 | I16: 4
E17: C | F17: C-CF4 | G17: =(I38-I37)/(H38-H37) -> 0.018052809 | H17: =(I37*H38-I38*H37)/(H38-H37) -> -81.097763 | I17: 4
E18: Cu | F18: Cu-CuF2 | G18: =(I44-I43)/(H44-H43) -> 0.031636051 | H18: =(I43*H44-I44*H43)/(H44-H43) -> -127.00677 | I18: 2
E19: Nb | F19: Nb-NbF5 | G19: =(I52-I51)/(H52-H51) -> 0.021402179 | H19: =(I51*H52-I52*H51)/(H52-H51) -> -167.24076 | I19: 5
E20: V | F20: V-VF3 | G20: =(I72-I71)/(H72-H71) -> 0.037455444 | H20: =(I71*H72-I72*H71)/(H72-H71) -> -189.98087 | I20: 3
E21: P | F21: P-PF3 | I21: 3
E22: S | F22: S-SF6 | G22: =(I70-I69)/(H70-H69) -> 0.033297209 | H22: =(I69*H70-I70*H69)/(H70-H69) -> -86.635598 | I22: 6
E23: B | F23: B-BF3 | G23: =(I40-I39)/(H40-H39) -> 0.010000601 | H23: =(I39*H40-I40*H39)/(H40-H39) -> -182.94135 | I23: 3
E24: Mg | F24: Mg-MgF2 | G24: =(I54-I53)/(H54-H53) -> 0.036130265 | H24: =(I53*H54-I54*H53)/(H54-H53) -> -257.40986 | I24: 2
E25: Sn | F25: Sn-SnF4 | I25: 4
E26: Zr | F26: Zr-ZrF4 | G26: =(I78-I77)/(H78-H77) -> 0.034329594 | H26: =(I77*H78-I78*H77)/(H78-H77) -> -222.46645 | I26: 4
E27: Y | F27: Y-YF3 | G27: =(I74-I73)/(H74-H73) -> 0.034089493 | H27: =(I73*H74-I74*H73)/(H74-H73) -> -264.64924 | I27: 3
D33: https://enispa.sharepoint.com/sites/Venicelaboratories-FLiNaKandFLiBecorrosion/Documenti%20condivisi/FLiNaK%20and%20FLiBe%20corrosion/Diagrammi%20dei%20potenziali%20di%20Ellingham%20Delta_G.pdf
D34: ELLINGHAM DIAGRAM GIBBS FREE ENERGY [kcal/gfw] DATA POINTS FOR LINEAR COEFFICIENTS
D36: Ellingham Diagram fir Selected Fluorides: Part-X | E36: Element | F36: ID | G36: point 1 or 2 | H36: X | I36: Y
D37: 1 | E37: C | F37: C-CF4 | G37: 1 | H37: -0.19193858 | I37: -81.101228
G38: 2 | H38: 2400.9597 | I38: -37.753696
D39: 1 | E39: B | F39: B-BF3 | G39: 1 | H39: 1.7274472 | I39: -182.92408
G40: 2 | H40: 2300.5118 | I40: -159.93485
D41: 1 | E41: Al | F41: Al-AlF3 | G41: 1 | H41: 931.66987 | I41: -180.95089
G42: 2 | H42: 1545.5534 | I42: -155.98847
D43: 2 | E43: Cu | F43: Cu-CuF2 | G43: 1 | H43: 1.4643803 | I43: -126.96045
G44: 2 | H44: 1200.065 | I44: -89.041454
D45: 2 | E45: Co | F45: Co-CoF2 | G45: 1 | H45: -0.48850539 | I45: -158.03487
G46: 2 | H46: 1475.2078 | I46: -108.2473
D47: 2 | E47: Cr | F47: Cr-CrF3 | G47: 1 | H47: 206.18472 | I47: -176.04947
G48: 2 | H48: 1372.7919 | I48: -136.03128
D49: 2 | E49: Fe | F49: Fe-FeF2 | G49: 1 | H49: 2.0978132 | I49: -167.03268
G50: 2 | H50: 1373.525 | I50: -123.24736
...

Sheet Corrosion dataset
A1: id_test_code | B1: Column1 | C1: institution | D1: year | E1: author | F1: id_paper | G1: test_condition | H1: Experimental Velocity [cm/s] | I1: temperature | J1: dive_time | K1: crucible | L1: id_material | M1: Plating | N1: density [g/m^3] | O1: Ni_wt | P1: Cr_wt | Q1: Mo_wt | R1: Fe_wt | S1: W_wt | T1: Co_wt | U1: Mn_wt | V1: Al_wt | W1: Ti_wt | X1: Si_wt | Y1: C_wt | Z1: Cu_wt | AA1: Nb_wt | AB1: V_wt | AC1: P_wt | AD1: S_wt | AE1: B_wt | AF1: Mg weight | AG1: Sn_wt | AH1: Zr_wt | AI1: O_wt | AJ1: N_wt | AK1: Y_wt | AL1: H_wt | AM1: Ni_mol | AN1: Cr_mol | AO1: Mo_mol | AP1: Fe_mol | AQ1: W_mol | AR1: Co_mol | AS1: Mn_mol | AT1: Al_mol | AU1: Ti_mol | AV1: Si_mol2 | AW1: C_mol | AX1: Cu_mol | AY1: Nb_mol | AZ1: V_mol | BA1: P_mol | BB1: S_mol | BC1: B_mol | BD1: Mg_mol | BE1: Sn_mol | BF1: Zr_mol | BG1: O_mol | BH1: N_mol | BI1: Y_mol | BJ1: H_mol | BK1: Ellingham ∆G [kcal/gfw] of material (approx. With Ni-Cr-Mo-Fe-W-Co-Mn-Al-Ti potential weighted by mol%) | BL1: Ellingham ∆G [kcal/gfw] of crucible (approx. With Ni-Cr-Mo-Fe-W-Co-Mn-Al-Ti potential weighted by mol%) | BM1: length_a_sample | BN1: length_b_sample | BO1: thickness_sample | BP1: molten_salt | BQ1: Salt Provenience | BR1: ms_purified | BS1: Residual Moisture wt.% | BT1: euf3 | BU1: Fe_ppmw impurity pre | BV1: S_ppmw impurity pre | BW1: P_ppmw impurity pre | BX1: Ca_ppmw impurity pre | BY1: Al_ppmw impurity pre | BZ1: Ni_ppmw impurity pre | CA1: Cr_ppmw impurity pre | CB1: Ti_ppmw impurity pre | CC1: Mo_ppmw impurity pre | CD1: Mg_ppmw impurity pre2 | CE1: Mn_ppmw impurity pre | CF1: Zn_ppmw impurity pre | CG1: HF_ppmw impurity pre | CH1: Zr_ppmw impurity pre | CI1: C_ppmw impurity pre | CJ1: W_ppmw impurity pre | CK1: Cu_ppmw impurity pre | CL1: Si_ppmw impurity pre | CM1: O2-_ppmw impurity pre | CN1: Te_ppmw impurity pre | CO1: Residual Moisture wt.% after | CP1: Fe_ppmw impurity after | CQ1: S_ppmw impurity after | CR1: P_ppmw impurity after | CS1: Ca_ppmw impurity after | CT1: Al_ppmw impurity after | CU1: Ni_ppmw impurity after | CV1: Cr_ppmw impurity after | CW1: Ti_ppmw impurity after | CX1: Mo_ppmw impurity after | CY1: Mg_ppmw impurity after | CZ1: Mn_ppmw impurity after | DA1: Zn_ppmw impurity after | DB1: HF_ppmw impurity after | DC1: Zr_ppmw impurity after | DD1: C_ppmw impurity after | DE1: W_ppmw impurity after | DF1: Cu_ppmw impurity after | DG1: Si_ppmw impurity after | DH1: O2-_ppmw impurity after | DI1: Te_ppmw impurity after | DJ1: radiation_exposure | DK1: beam_energy | DL1: Beam Current density[uA/cm^2] | DM1: max_depth_selective_diss [um] | DN1: sem_um_y | DO1: weight_loss [mg/cm^2] | DP1: average_normalized_corrosion_depth | DQ1: C0_Cr | DR1: corrosion_class | DS1: reliability | DT1: Link To Paper | DU1: note | DW1: Somma composizione massa | DY1: Somma composizione moli
A2: A0316 L SS2015Zheng | B2: 0 | C2: University of Wisconsin Madison | D2: 2018 | E2: Zheng | F2: A0 | G2: static | H2: 0 | I2: 700 | J2: 1000 | K2: 316 L SS | L2: 316 L SS | N2: 7980000 | O2: 10.025 | P2: 16.825 | Q2: 2.0115 | R2: =100-SUM(_2025_01_07T12_47_export3[[#This Row],[Ni_wt]:[Mo_wt]],_2025_01_07T12_47_export3[[#This Row],[W_wt]:[H_wt]]) -> 68.6109 | U2: 1.5305 | X2: 0.309 | Y2: 0.225 | Z2: 0.3795 | AC2: 0.031 | AD2: 0.0016 | AJ2: 0.051 | AM2: =100*(O2/BD$343)/($O2/$BD$343+$P2/$BD$344+$Q2/$BD$346+$R2/$BD$348+$S2/$BD$350+$T2/$BD$351+$U2/$BD$352+$V2/$BD$353+$W2/$BD$354+$X2/$BD$359+$Y2/$BD$360+$Z2/$BD$361+$AA2/$BD$362+$AB2/$BD$363+$AC2/$BD$364+$AD2/$BD$365+$AE2/$BD$366+$AF2/$BD$367+$AG2/$BD$369+$AH2/$BD$355+$AI2/$BD$356+$AJ2/$BD$357+$AK2/$BD$368+$AL2/$BD$358) -> 9.4263736 | AN2: =100*(P2/BD$344)/($O2/$BD$343+$P2/$BD$344+$Q2/$BD$346+$R2/$BD$348+$S2/$BD$350+$T2/$BD$351+$U2/$BD$352+$V2/$BD$353+$W2/$BD$354+$X2/$BD$359+$Y2/$BD$360+$Z2/$BD$361+$AA2/$BD$362+$AB2/$BD$363+$AC2/$BD$364+$AD2/$BD$365+$AE2/$BD$366+$AF2/$BD$367+$AG2/$BD$369+$AH2/$BD$355+$AI2/$BD$356+$AJ2/$BD$357+$AK2/$BD$368+$AL2/$BD$358) -> 17.855668 | AO2: =100*(Q2/BD$346)/($O2/$BD$343+$P2/$BD$344+$Q2/$BD$346+$R2/$BD$348+$S2/$BD$350+$T2/$BD$351+$U2/$BD$352+$V2/$BD$353+$W2/$BD$354+$X2/$BD$359+$Y2/$BD$360+$Z2/$BD$361+$AA2/$BD$362+$AB2/$BD$363+$AC2/$BD$364+$AD2/$BD$365+$AE2/$BD$366+$AF2/$BD$367+$AG2/$BD$369+$AH2/$BD$355+$AI2/$BD$356+$AJ2/$BD$357+$AK2/$BD$368+$AL2/$BD$358) -> 1.1567891 | AP2: =100*(R2/BD$348)/($O2/$BD$343+$P2/$BD$344+$Q2/$BD$346+$R2/$BD$348+$S2/$BD$350+$T2/$BD$351+$U2/$BD$352+$V2/$BD$353+$W2/$BD$354+$X2/$BD$359+$Y2/$BD$360+$Z2/$BD$361+$AA2/$BD$362+$AB2/$BD$363+$AC2/$BD$364+$AD2/$BD$365+$AE2/$BD$366+$AF2/$BD$367+$AG2/$BD$369+$AH2/$BD$355+$AI2/$BD$356+$AJ2/$BD$357+$AK2/$BD$368+$AL2/$BD$358) -> 67.794477 | AQ2: =100*(S2/BD$350)/($O2/$BD$343+$P2/$BD$344+$Q2/$BD$346+$R2/$BD$348+$S2/$BD$350+$T2/$BD$351+$U2/$BD$352+$V2/$BD$353+$W2/$BD$354+$X2/$BD$359+$Y2/$BD$360+$Z2/$BD$361+$AA2/$BD$362+$AB2/$BD$363+$AC2/$BD$364+$AD2/$BD$365+$AE2/$BD$366+$AF2/$BD$367+$AG2/$BD$369+$AH2/$BD$355+$AI2/$BD$356+$AJ2/$BD$357+$AK2/$BD$368+$AL2/$BD$358) -> 0 | AR2: =100*(T2/BD$351)/($O2/$BD$343+$P2/$BD$344+$Q2/$BD$346+$R2/$BD$348+$S2/$BD$350+$T2/$BD$351+$U2/$BD$352+$V2/$BD$353+$W2/$BD$354+$X2/$BD$359+$Y2/$BD$360+$Z2/$BD$361+$AA2/$BD$362+$AB2/$BD$363+$AC2/$BD$364+$AD2/$BD$365+$AE2/$BD$366+$AF2/$BD$367+$AG2/$BD$369+$AH2/$BD$355+$AI2/$BD$356+$AJ2/$BD$357+$AK2/$BD$368+$AL2/$BD$358) -> 0 | AS2: =100*(U2/BD$352)/($O2/$BD$343+$P2/$BD$344+$Q2/$BD$346+$R2/$BD$348+$S2/$BD$350+$T2/$BD$351+$U2/$BD$352+$V2/$BD$353+$W2/$BD$354+$X2/$BD$359+$Y2/$BD$360+$Z2/$BD$361+$AA2/$BD$362+$AB2/$BD$363+$AC2/$BD$364+$AD2/$BD$365+$AE2/$BD$366+$AF2/$BD$367+$AG2/$BD$369+$AH2/$BD$355+$AI2/$BD$356+$AJ2/$BD$357+$AK2/$BD$368+$AL2/$BD$358) -> 1.5373369 | AT2: =100*(V2/BD$353)/($O2/$BD$343+$P2/$BD$344+$Q2/$BD$346+$R2/$BD$348+$S2/$BD$350+$T2/$BD$351+$U2/$BD$352+$V2/$BD$353+$W2/$BD$354+$X2/$BD$359+$Y2/$BD$360+$Z2/$BD$361+$AA2/$BD$362+$AB2/$BD$363+$AC2/$BD$364+$AD2/$BD$365+$AE2/$BD$366+$AF2/$BD$367+$AG2/$BD$369+$AH2/$BD$355+$AI2/$BD$356+$AJ2/$BD$357+$AK2/$BD$368+$AL2/$BD$358) -> 0 | AU2: =100*(W2/BD$354)/($O2/$BD$343+$P2/$BD$344+$Q2/$BD$346+$R2/$BD$348+$S2/$BD$350+$T2/$BD$351+$U2/$BD$352+$V2/$BD$353+$W2/$BD$354+$X2/$BD$359+$Y2/$BD$360+$Z2/$BD$361+$AA2/$BD$362+$AB2/$BD$363+$AC2/$BD$364+$AD2/$BD$365+$AE2/$BD$366+$AF2/$BD$367+$AG2/$BD$369+$AH2/$BD$355+$AI2/$BD$356+$AJ2/$BD$357+$AK2/$BD$368+$AL2/$BD$358) -> 0 | AV2: =100*(X2/BD$359)/($O2/$BD$343+$P2/$BD$344+$Q2/$BD$346+$R2/$BD$348+$S2/$BD$350+$T2/$BD$351+$U2/$BD$352+$V2/$BD$353+$W2/$BD$354+$X2/$BD$359+$Y2/$BD$360+$Z2/$BD$361+$AA2/$BD$362+$AB2/$BD$363+$AC2/$BD$364+$AD2/$BD$365+$AE2/$BD$366+$AF2/$BD$367+$AG2/$BD$369+$AH2/$BD$355+$AI2/$BD$356+$AJ2/$BD$357+$AK2/$BD$368+$AL2/$BD$358) -> 0.6070593 | AW2: =100*(Y2/BD$360)/($O2/$BD$343+$P2/$BD$344+$Q2/$BD$346+$R2/$BD$348+$S2/$BD$350+$T2/$BD$351+$U2/$BD$352+$V2/$BD$353+$W2/$BD$354+$X2/$BD$359+$Y2/$BD$360+$Z2/$BD$361+$AA2/$BD$362+$AB2/$BD$363+$AC2/$BD$364+$AD2/$BD$365+$AE2/$BD$366+$AF2/$BD$367+$AG2/$BD$369+$AH2/$BD$355+$AI2/$BD$356+$AJ2/$BD$357+$AK2/$BD$368+$AL2/$BD$358) -> 1.0338651 | AX2: =100*(Z2/BD$361)/($O2/$BD$343+$P2/$BD$344+$Q2/$BD$346+$R2/$BD$348+$S2/$BD$350+$T2/$BD$351+$U2/$BD$352+$V2/$BD$353+$W2/$BD$354+$X2/$BD$359+$Y2/$BD$360+$Z2/$BD$361+$AA2/$BD$362+$AB2/$BD$363+$AC2/$BD$364+$AD2/$BD$365+$AE2/$BD$366+$AF2/$BD$367+$AG2/$BD$369+$AH2/$BD$355+$AI2/$BD$356+$AJ2/$BD$357+$AK2/$BD$368+$AL2/$BD$358) -> 0.32954946 | AY2: =100*(AA2/BD$362)/($O2/$BD$343+$P2/$BD$344+$Q2/$BD$346+$R2/$BD$348+$S2/$BD$350+$T2/$BD$351+$U2/$BD$352+$V2/$BD$353+$W2/$BD$354+$X2/$BD$359+$Y2/$BD$360+$Z2/$BD$361+$AA2/$BD$362+$AB2/$BD$363+$AC2/$BD$364+$AD2/$BD$365+$AE2/$BD$366+$AF2/$BD$367+$AG2/$BD$369+$AH2/$BD$355+$AI2/$BD$356+$AJ2/$BD$357+$AK2/$BD$368+$AL2/$BD$358) -> 0 | AZ2: =100*(AB2/BD$363)/($O2/$BD$343+$P2/$BD$344+$Q2/$BD$346+$R2/$BD$348+$S2/$BD$350+$T2/$BD$351+$U2/$BD$352+$V2/$BD$353+$W2/$BD$354+$X2/$BD$359+$Y2/$BD$360+$Z2/$BD$361+$AA2/$BD$362+$AB2/$BD$363+$AC2/$BD$364+$AD2/$BD$365+$AE2/$BD$366+$AF2/$BD$367+$AG2/$BD$369+$AH2/$BD$355+$AI2/$BD$356+$AJ2/$BD$357+$AK2/$BD$368+$AL2/$BD$358) -> 0 | BA2: =100*(AC2/BD$364)/($O2/$BD$343+$P2/$BD$344+$Q2/$BD$346+$R2/$BD$348+$S2/$BD$350+$T2/$BD$351+$U2/$BD$352+$V2/$BD$353+$W2/$BD$354+$X2/$BD$359+$Y2/$BD$360+$Z2/$BD$361+$AA2/$BD$362+$AB2/$BD$363+$AC2/$BD$364+$AD2/$BD$365+$AE2/$BD$366+$AF2/$BD$367+$AG2/$BD$369+$AH2/$BD$355+$AI2/$BD$356+$AJ2/$BD$357+$AK2/$BD$368+$AL2/$BD$358) -> 0.05523888 | BB2: =100*(AD2/BD$365)/($O2/$BD$343+$P2/$BD$344+$Q2/$BD$346+$R2/$BD$348+$S2/$BD$350+$T2/$BD$351+$U2/$BD$352+$V2/$BD$353+$W2/$BD$354+$X2/$BD$359+$Y2/$BD$360+$Z2/$BD$361+$AA2/$BD$362+$AB2/$BD$363+$AC2/$BD$364+$AD2/$BD$365+$AE2/$BD$366+$AF2/$BD$367+$AG2/$BD$369+$AH2/$BD$355+$AI2/$BD$356+$AJ2/$BD$357+$AK2/$BD$368+$AL2/$BD$358) -> 0.0027532484 | BC2: =100*(AE2/BD$366)/($O2/$BD$343+$P2/$BD$344+$Q2/$BD$346+$R2/$BD$348+$S2/$BD$350+$T2/$BD$351+$U2/$BD$352+$V2/$BD$353+$W2/$BD$354+$X2/$BD$359+$Y2/$BD$360+$Z2/$BD$361+$AA2/$BD$362+$AB2/$BD$363+$AC2/$BD$364+$AD2/$BD$365+$AE2/$BD$366+$AF2/$BD$367+$AG2/$BD$369+$AH2/$BD$355+$AI2/$BD$356+$AJ2/$BD$357+$AK2/$BD$368+$AL2/$BD$358) -> 0 | BD2: =100*(AF2/BD$367)/($O2/$BD$343+$P2/$BD$344+$Q2/$BD$346+$R2/$BD$348+$S2/$BD$350+$T2/$BD$351+$U2/$BD$352+$V2/$BD$353+$W2/$BD$354+$X2/$BD$359+$Y2/$BD$360+$Z2/$BD$361+$AA2/$BD$362+$AB2/$BD$363+$AC2/$BD$364+$AD2/$BD$365+$AE2/$BD$366+$AF2/$BD$367+$AG2/$BD$369+$AH2/$BD$355+$AI2/$BD$356+$AJ2/$BD$357+$AK2/$BD$368+$AL2/$BD$358) -> 0 | BE2: =100*(AG2/BD$369)/($O2/$BD$343+$P2/$BD$344+$Q2/$BD$346+$R2/$BD$348+$S2/$BD$350+$T2/$BD$351+$U2/$BD$352+$V2/$BD$353+$W2/$BD$354+$X2/$BD$359+$Y2/$BD$360+$Z2/$BD$361+$AA2/$BD$362+$AB2/$BD$363+$AC2/$BD$364+$AD2/$BD$365+$AE2/$BD$366+$AF2/$BD$367+$AG2/$BD$369+$AH2/$BD$355+$AI2/$BD$356+$AJ2/$BD$357+$AK2/$BD$368+$AL2/$BD$358) -> 0 | BF2: =100*(AH2/BD$355)/($O2/$BD$343+$P2/$BD$344+$Q2/$BD$346+$R2/$BD$348+$S2/$BD$350+$T2/$BD$351+$U2/$BD$352+$V2/$BD$353+$W2/$BD$354+$X2/$BD$359+$Y2/$BD$360+$Z2/$BD$361+$AA2/$BD$362+$AB2/$BD$363+$AC2/$BD$364+$AD2/$BD$365+$AE2/$BD$366+$AF2/$BD$367+$AG2/$BD$369+$AH2/$BD$355+$AI2/$BD$356+$AJ2/$BD$357+$AK2/$BD$368+$AL2/$BD$358) -> 0 | BG2: =100*(AI2/BD$356)/($O2/$BD$343+$P2/$BD$344+$Q2/$BD$346+$R2/$BD$348+$S2/$BD$350+$T2/$BD$351+$U2/$BD$352+$V2/$BD$353+$W2/$BD$354+$X2/$BD$359+$Y2/$BD$360+$Z2/$BD$361+$AA2/$BD$362+$AB2/$BD$363+$AC2/$BD$364+$AD2/$BD$365+$AE2/$BD$366+$AF2/$BD$367+$AG2/$BD$369+$AH2/$BD$355+$AI2/$BD$356+$AJ2/$BD$357+$AK2/$BD$368+$AL2/$BD$358) -> 0 | BH2: =100*(AJ2/BD$357)/($O2/$BD$343+$P2/$BD$344+$Q2/$BD$346+$R2/$BD$348+$S2/$BD$350+$T2/$BD$351+$U2/$BD$352+$V2/$BD$353+$W2/$BD$354+$X2/$BD$359+$Y2/$BD$360+$Z2/$BD$361+$AA2/$BD$362+$AB2/$BD$363+$AC2/$BD$364+$AD2/$BD$365+$AE2/$BD$366+$AF2/$BD$367+$AG2/$BD$369+$AH2/$BD$355+$AI2/$BD$356+$AJ2/$BD$357+$AK2/$BD$368+$AL2/$BD$358) -> 0.20088912 | BI2: =100*(AK2/BD$368)/($O2/$BD$343+$P2/$BD$344+$Q2/$BD$346+$R2/$BD$348+$S2/$BD$350+$T2/$BD$351+$U2/$BD$352+$V2/$BD$353+$W2/$BD$354+$X2/$BD$359+$Y2/$BD$360+$Z2/$BD$361+$AA2/$BD$362+$AB2/$BD$363+$AC2/$BD$364+$AD2/$BD$365+$AE2/$BD$366+$AF2/$BD$367+$AG2/$BD$369+$AH2/$BD$355+$AI2/$BD$356+$AJ2/$BD$357+$AK2/$BD$368+$AL2/$BD$358) -> 0 | BJ2: =100*(AL2/BD$358)/($O2/$BD$343+$P2/$BD$344+$Q2/$BD$346+$R2/$BD$348+$S2/$BD$350+$T2/$BD$351+$U2/$BD$352+$V2/$BD$353+$W2/$BD$354+$X2/$BD$359+$Y2/$BD$360+$Z2/$BD$361+$AA2/$BD$362+$AB2/$BD$363+$AC2/$BD$364+$AD2/$BD$365+$AE2/$BD$366+$AF2/$BD$367+$AG2/$BD$369+$AH2/$BD$355+$AI2/$BD$356+$AJ2/$BD$357+$AK2/$BD$368+$AL2/$BD$358) -> 0 | BK2: =(($AM2*($BK$396+$BJ$396*($BM$389+$I2))+$AN2*($BK$397+$BJ$397*($BM$389+$I2))+$AO2*($BK$398+$BJ$398*($BM$389+$I2))+$AP2*($BK$399+$BJ$399*($BM$389+$I2))+$AR2*($BK$401+$BJ$401*($BM$389+$I2))+$AS2*($BK$402+$BJ$402*($BM$389+$I2))+$AT2*($BK$403+$BJ$403*($BM$389+$I2))+$AU2*($BK$404+$BJ$404*($BM$389+$I2))+$AV2*($BK$405+$BJ$405*($BM$389+$I2))+$AW2*($BK$406+$BJ$406*($BM$389+$I2))+$AX2*($BK$407+$BJ$407*($BM$389+$I2))+$AY2*($BK$408+$BJ$408*($BM$389+$I2))+$AZ2*($BK$409+$BJ$409*($BM$389+$I2))+$BB2*($BK$411+$BJ$411*($BM$389+$I2))+$BC2*($BK$412+$BJ$412*($BM$389+$I2))+$BD2*($BK$413+$BJ$413*($BM$389+$I2))+$BF2*($BK$415+$BJ$415*($BM$389+$I2))+$BI2*($BK$416+$BJ$416*($BM$389+$I2)))/(SUM($AM2:$BJ2)-$AQ2-$BA2-$BE2-$BG2-$BH2-$BJ2)) -> -136.54296 | BL2: =IF($K2=$L2,$BK2,IF(OR($K2="graphite",$K2="vitreous carbon"),$BK$406+($BM$389+$I2)*$BJ$406,IF($K2="Pyrolytic Boron Nitride","PBN",IF(COUNTIF($BH$396:$BH$416,$K2)>0,VLOOKUP($K2,$BH$396:$BK$416,4,FALSE)+($BM$389+$I2)*VLOOKUP($K2,$BH$396:$BK$416,3,FALSE),IF(COUNTIF($L1:$L$247,$K2)>0,VLOOKUP($K2,$L1:$BK$247,52,FALSE),"idk"))))) -> -136.54296 | BM2: 13 | BN2: 7 | BO2: 1 | BP2: FLiBe | BQ2: ORNL | BR2: yes | BT2: 0 | DJ2: 0 | DK2: 0 | DM2: -6.4 | DN2: -17.1 | DO2: -0.22 | DT2: https://enispa.sharepoint.com/sites/Venicelaboratories-FLiNaKandFLiBecorrosion/Documenti%20condivisi/FLiNaK%20and%20FLiBe%20corrosion/3.%20Letteratura/Attività%202023/2015_Zheng_PhD_Corrosion%20Behavior%20of%20Alloys%20in%20Molten%20Fluoride%20Salts.pdf | DU2: Composizione NOMINALE dei provini | DW2: =SUM(_2025_01_07T12_47_export3[[#This Row],[Ni_wt]:[H_wt]]) -> 100 | DY2: =SUM($AM2:BJ2) -> 100
A3: A0316 L SS2015Zheng | B3: 1 | C3: University of Wisconsin Madison | D3: 2019 | E3: Zheng | F3: A0 | G3: static | H3: 0 | I3: 700 | J3: 1000 | K3: graphite | L3: 316 L SS | N3: 7980000 | O3: 10.025 | P3: 16.825 | Q3: 2.0115 | R3: =100-SUM(_2025_01_07T12_47_export3[[#This Row],[Ni_wt]:[Mo_wt]],_2025_01_07T12_47_export3[[#This Row],[W_wt]:[H_wt]]) -> 68.6109 | U3: 1.5305 | X3: 0.309 | Y3: 0.225 | Z3: 0.3795 | AC3: 0.031 | AD3: 0.0016 | AJ3: 0.051 | AM3: =100*(O3/BD$343)/($O3/$BD$343+$P3/$BD$344+$Q3/$BD$346+$R3/$BD$348+$S3/$BD$350+$T3/$BD$351+$U3/$BD$352+$V3/$BD$353+$W3/$BD$354+$X3/$BD$359+$Y3/$BD$360+$Z3/$BD$361+$AA3/$BD$362+$AB3/$BD$363+$AC3/$BD$364+$AD3/$BD$365+$AE3/$BD$366+$AF3/$BD$367+$AG3/$BD$369+$AH3/$BD$355+$AI3/$BD$356+$AJ3/$BD$357+$AK3/$BD$368+$AL3/$BD$358) -> 9.4263736 | AN3: =100*(P3/BD$344)/($O3/$BD$343+$P3/$BD$344+$Q3/$BD$346+$R3/$BD$348+$S3/$BD$350+$T3/$BD$351+$U3/$BD$352+$V3/$BD$353+$W3/$BD$354+$X3/$BD$359+$Y3/$BD$360+$Z3/$BD$361+$AA3/$BD$362+$AB3/$BD$363+$AC3/$BD$364+$AD3/$BD$365+$AE3/$BD$366+$AF3/$BD$367+$AG3/$BD$369+$AH3/$BD$355+$AI3/$BD$356+$AJ3/$BD$357+$AK3/$BD$368+$AL3/$BD$358) -> 17.855668 | AO3: =100*(Q3/BD$346)/($O3/$BD$343+$P3/$BD$344+$Q3/$BD$346+$R3/$BD$348+$S3/$BD$350+$T3/$BD$351+$U3/$BD$352+$V3/$BD$353+$W3/$BD$354+$X3/$BD$359+$Y3/$BD$360+$Z3/$BD$361+$AA3/$BD$362+$AB3/$BD$363+$AC3/$BD$364+$AD3/$BD$365+$AE3/$BD$366+$AF3/$BD$367+$AG3/$BD$369+$AH3/$BD$355+$AI3/$BD$356+$AJ3/$BD$357+$AK3/$BD$368+$AL3/$BD$358) -> 1.1567891 | AP3: =100*(R3/BD$348)/($O3/$BD$343+$P3/$BD$344+$Q3/$BD$346+$R3/$BD$348+$S3/$BD$350+$T3/$BD$351+$U3/$BD$352+$V3/$BD$353+$W3/$BD$354+$X3/$BD$359+$Y3/$BD$360+$Z3/$BD$361+$AA3/$BD$362+$AB3/$BD$363+$AC3/$BD$364+$AD3/$BD$365+$AE3/$BD$366+$AF3/$BD$367+$AG3/$BD$369+$AH3/$BD$355+$AI3/$BD$356+$AJ3/$BD$357+$AK3/$BD$368+$AL3/$BD$358) -> 67.794477 | AQ3: =100*(S3/BD$350)/($O3/$BD$343+$P3/$BD$344+$Q3/$BD$346+$R3/$BD$348+$S3/$BD$350+$T3/$BD$351+$U3/$BD$352+$V3/$BD$353+$W3/$BD$354+$X3/$BD$359+$Y3/$BD$360+$Z3/$BD$361+$AA3/$BD$362+$AB3/$BD$363+$AC3/$BD$364+$AD3/$BD$365+$AE3/$BD$366+$AF3/$BD$367+$AG3/$BD$369+$AH3/$BD$355+$AI3/$BD$356+$AJ3/$BD$357+$AK3/$BD$368+$AL3/$BD$358) -> 0 | AR3: =100*(T3/BD$351)/($O3/$BD$343+$P3/$BD$344+$Q3/$BD$346+$R3/$BD$348+$S3/$BD$350+$T3/$BD$351+$U3/$BD$352+$V3/$BD$353+$W3/$BD$354+$X3/$BD$359+$Y3/$BD$360+$Z3/$BD$361+$AA3/$BD$362+$AB3/$BD$363+$AC3/$BD$364+$AD3/$BD$365+$AE3/$BD$366+$AF3/$BD$367+$AG3/$BD$369+$AH3/$BD$355+$AI3/$BD$356+$AJ3/$BD$357+$AK3/$BD$368+$AL3/$BD$358) -> 0 | AS3: =100*(U3/BD$352)/($O3/$BD$343+$P3/$BD$344+$Q3/$BD$346+$R3/$BD$348+$S3/$BD$350+$T3/$BD$351+$U3/$BD$352+$V3/$BD$353+$W3/$BD$354+$X3/$BD$359+$Y3/$BD$360+$Z3/$BD$361+$AA3/$BD$362+$AB3/$BD$363+$AC3/$BD$364+$AD3/$BD$365+$AE3/$BD$366+$AF3/$BD$367+$AG3/$BD$369+$AH3/$BD$355+$AI3/$BD$356+$AJ3/$BD$357+$AK3/$BD$368+$AL3/$BD$358) -> 1.5373369 | AT3: =100*(V3/BD$353)/($O3/$BD$343+$P3/$BD$344+$Q3/$BD$346+$R3/$BD$348+$S3/$BD$350+$T3/$BD$351+$U3/$BD$352+$V3/$BD$353+$W3/$BD$354+$X3/$BD$359+$Y3/$BD$360+$Z3/$BD$361+$AA3/$BD$362+$AB3/$BD$363+$AC3/$BD$364+$AD3/$BD$365+$AE3/$BD$366+$AF3/$BD$367+$AG3/$BD$369+$AH3/$BD$355+$AI3/$BD$356+$AJ3/$BD$357+$AK3/$BD$368+$AL3/$BD$358) -> 0 | AU3: =100*(W3/BD$354)/($O3/$BD$343+$P3/$BD$344+$Q3/$BD$346+$R3/$BD$348+$S3/$BD$350+$T3/$BD$351+$U3/$BD$352+$V3/$BD$353+$W3/$BD$354+$X3/$BD$359+$Y3/$BD$360+$Z3/$BD$361+$AA3/$BD$362+$AB3/$BD$363+$AC3/$BD$364+$AD3/$BD$365+$AE3/$BD$366+$AF3/$BD$367+$AG3/$BD$369+$AH3/$BD$355+$AI3/$BD$356+$AJ3/$BD$357+$AK3/$BD$368+$AL3/$BD$358) -> 0 | AV3: =100*(X3/BD$359)/($O3/$BD$343+$P3/$BD$344+$Q3/$BD$346+$R3/$BD$348+$S3/$BD$350+$T3/$BD$351+$U3/$BD$352+$V3/$BD$353+$W3/$BD$354+$X3/$BD$359+$Y3/$BD$360+$Z3/$BD$361+$AA3/$BD$362+$AB3/$BD$363+$AC3/$BD$364+$AD3/$BD$365+$AE3/$BD$366+$AF3/$BD$367+$AG3/$BD$369+$AH3/$BD$355+$AI3/$BD$356+$AJ3/$BD$357+$AK3/$BD$368+$AL3/$BD$358) -> 0.6070593 | AW3: =100*(Y3/BD$360)/($O3/$BD$343+$P3/$BD$344+$Q3/$BD$346+$R3/$BD$348+$S3/$BD$350+$T3/$BD$351+$U3/$BD$352+$V3/$BD$353+$W3/$BD$354+$X3/$BD$359+$Y3/$BD$360+$Z3/$BD$361+$AA3/$BD$362+$AB3/$BD$363+$AC3/$BD$364+$AD3/$BD$365+$AE3/$BD$366+$AF3/$BD$367+$AG3/$BD$369+$AH3/$BD$355+$AI3/$BD$356+$AJ3/$BD$357+$AK3/$BD$368+$AL3/$BD$358) -> 1.0338651 | AX3: =100*(Z3/BD$361)/($O3/$BD$343+$P3/$BD$344+$Q3/$BD$346+$R3/$BD$348+$S3/$BD$350+$T3/$BD$351+$U3/$BD$352+$V3/$BD$353+$W3/$BD$354+$X3/$BD$359+$Y3/$BD$360+$Z3/$BD$361+$AA3/$BD$362+$AB3/$BD$363+$AC3/$BD$364+$AD3/$BD$365+$AE3/$BD$366+$AF3/$BD$367+$AG3/$BD$369+$AH3/$BD$355+$AI3/$BD$356+$AJ3/$BD$357+$AK3/$BD$368+$AL3/$BD$358) -> 0.32954946 | AY3: =100*(AA3/BD$362)/($O3/$BD$343+$P3/$BD$344+$Q3/$BD$346+$R3/$BD$348+$S3/$BD$350+$T3/$BD$351+$U3/$BD$352+$V3/$BD$353+$W3/$BD$354+$X3/$BD$359+$Y3/$BD$360+$Z3/$BD$361+$AA3/$BD$362+$AB3/$BD$363+$AC3/$BD$364+$AD3/$BD$365+$AE3/$BD$366+$AF3/$BD$367+$AG3/$BD$369+$AH3/$BD$355+$AI3/$BD$356+$AJ3/$BD$357+$AK3/$BD$368+$AL3/$BD$358) -> 0 | AZ3: =100*(AB3/BD$363)/($O3/$BD$343+$P3/$BD$344+$Q3/$BD$346+$R3/$BD$348+$S3/$BD$350+$T3/$BD$351+$U3/$BD$352+$V3/$BD$353+$W3/$BD$354+$X3/$BD$359+$Y3/$BD$360+$Z3/$BD$361+$AA3/$BD$362+$AB3/$BD$363+$AC3/$BD$364+$AD3/$BD$365+$AE3/$BD$366+$AF3/$BD$367+$AG3/$BD$369+$AH3/$BD$355+$AI3/$BD$356+$AJ3/$BD$357+$AK3/$BD$368+$AL3/$BD$358) -> 0 | BA3: =100*(AC3/BD$364)/($O3/$BD$343+$P3/$BD$344+$Q3/$BD$346+$R3/$BD$348+$S3/$BD$350+$T3/$BD$351+$U3/$BD$352+$V3/$BD$353+$W3/$BD$354+$X3/$BD$359+$Y3/$BD$360+$Z3/$BD$361+$AA3/$BD$362+$AB3/$BD$363+$AC3/$BD$364+$AD3/$BD$365+$AE3/$BD$366+$AF3/$BD$367+$AG3/$BD$369+$AH3/$BD$355+$AI3/$BD$356+$AJ3/$BD$357+$AK3/$BD$368+$AL3/$BD$358) -> 0.05523888 | BB3: =100*(AD3/BD$365)/($O3/$BD$343+$P3/$BD$344+$Q3/$BD$346+$R3/$BD$348+$S3/$BD$350+$T3/$BD$351+$U3/$BD$352+$V3/$BD$353+$W3/$BD$354+$X3/$BD$359+$Y3/$BD$360+$Z3/$BD$361+$AA3/$BD$362+$AB3/$BD$363+$AC3/$BD$364+$AD3/$BD$365+$AE3/$BD$366+$AF3/$BD$367+$AG3/$BD$369+$AH3/$BD$355+$AI3/$BD$356+$AJ3/$BD$357+$AK3/$BD$368+$AL3/$BD$358) -> 0.0027532484 | BC3: =100*(AE3/BD$366)/($O3/$BD$343+$P3/$BD$344+$Q3/$BD$346+$R3/$BD$348+$S3/$BD$350+$T3/$BD$351+$U3/$BD$352+$V3/$BD$353+$W3/$BD$354+$X3/$BD$359+$Y3/$BD$360+$Z3/$BD$361+$AA3/$BD$362+$AB3/$BD$363+$AC3/$BD$364+$AD3/$BD$365+$AE3/$BD$366+$AF3/$BD$367+$AG3/$BD$369+$AH3/$BD$355+$AI3/$BD$356+$AJ3/$BD$357+$AK3/$BD$368+$AL3/$BD$358) -> 0 | BD3: =100*(AF3/BD$367)/($O3/$BD$343+$P3/$BD$344+$Q3/$BD$346+$R3/$BD$348+$S3/$BD$350+$T3/$BD$351+$U3/$BD$352+$V3/$BD$353+$W3/$BD$354+$X3/$BD$359+$Y3/$BD$360+$Z3/$BD$361+$AA3/$BD$362+$AB3/$BD$363+$AC3/$BD$364+$AD3/$BD$365+$AE3/$BD$366+$AF3/$BD$367+$AG3/$BD$369+$AH3/$BD$355+$AI3/$BD$356+$AJ3/$BD$357+$AK3/$BD$368+$AL3/$BD$358) -> 0 | BE3: =100*(AG3/BD$369)/($O3/$BD$343+$P3/$BD$344+$Q3/$BD$346+$R3/$BD$348+$S3/$BD$350+$T3/$BD$351+$U3/$BD$352+$V3/$BD$353+$W3/$BD$354+$X3/$BD$359+$Y3/$BD$360+$Z3/$BD$361+$AA3/$BD$362+$AB3/$BD$363+$AC3/$BD$364+$AD3/$BD$365+$AE3/$BD$366+$AF3/$BD$367+$AG3/$BD$369+$AH3/$BD$355+$AI3/$BD$356+$AJ3/$BD$357+$AK3/$BD$368+$AL3/$BD$358) -> 0 | BF3: =100*(AH3/BD$355)/($O3/$BD$343+$P3/$BD$344+$Q3/$BD$346+$R3/$BD$348+$S3/$BD$350+$T3/$BD$351+$U3/$BD$352+$V3/$BD$353+$W3/$BD$354+$X3/$BD$359+$Y3/$BD$360+$Z3/$BD$361+$AA3/$BD$362+$AB3/$BD$363+$AC3/$BD$364+$AD3/$BD$365+$AE3/$BD$366+$AF3/$BD$367+$AG3/$BD$369+$AH3/$BD$355+$AI3/$BD$356+$AJ3/$BD$357+$AK3/$BD$368+$AL3/$BD$358) -> 0 | BG3: =100*(AI3/BD$356)/($O3/$BD$343+$P3/$BD$344+$Q3/$BD$346+$R3/$BD$348+$S3/$BD$350+$T3/$BD$351+$U3/$BD$352+$V3/$BD$353+$W3/$BD$354+$X3/$BD$359+$Y3/$BD$360+$Z3/$BD$361+$AA3/$BD$362+$AB3/$BD$363+$AC3/$BD$364+$AD3/$BD$365+$AE3/$BD$366+$AF3/$BD$367+$AG3/$BD$369+$AH3/$BD$355+$AI3/$BD$356+$AJ3/$BD$357+$AK3/$BD$368+$AL3/$BD$358) -> 0 | BH3: =100*(AJ3/BD$357)/($O3/$BD$343+$P3/$BD$344+$Q3/$BD$346+$R3/$BD$348+$S3/$BD$350+$T3/$BD$351+$U3/$BD$352+$V3/$BD$353+$W3/$BD$354+$X3/$BD$359+$Y3/$BD$360+$Z3/$BD$361+$AA3/$BD$362+$AB3/$BD$363+$AC3/$BD$364+$AD3/$BD$365+$AE3/$BD$366+$AF3/$BD$367+$AG3/$BD$369+$AH3/$BD$355+$AI3/$BD$356+$AJ3/$BD$357+$AK3/$BD$368+$AL3/$BD$358) -> 0.20088912 | BI3: =100*(AK3/BD$368)/($O3/$BD$343+$P3/$BD$344+$Q3/$BD$346+$R3/$BD$348+$S3/$BD$350+$T3/$BD$351+$U3/$BD$352+$V3/$BD$353+$W3/$BD$354+$X3/$BD$359+$Y3/$BD$360+$Z3/$BD$361+$AA3/$BD$362+$AB3/$BD$363+$AC3/$BD$364+$AD3/$BD$365+$AE3/$BD$366+$AF3/$BD$367+$AG3/$BD$369+$AH3/$BD$355+$AI3/$BD$356+$AJ3/$BD$357+$AK3/$BD$368+$AL3/$BD$358) -> 0 | BJ3: =100*(AL3/BD$358)/($O3/$BD$343+$P3/$BD$344+$Q3/$BD$346+$R3/$BD$348+$S3/$BD$350+$T3/$BD$351+$U3/$BD$352+$V3/$BD$353+$W3/$BD$354+$X3/$BD$359+$Y3/$BD$360+$Z3/$BD$361+$AA3/$BD$362+$AB3/$BD$363+$AC3/$BD$364+$AD3/$BD$365+$AE3/$BD$366+$AF3/$BD$367+$AG3/$BD$369+$AH3/$BD$355+$AI3/$BD$356+$AJ3/$BD$357+$AK3/$BD$368+$AL3/$BD$358) -> 0 | BK3: =(($AM3*($BK$396+$BJ$396*($BM$389+$I3))+$AN3*($BK$397+$BJ$397*($BM$389+$I3))+$AO3*($BK$398+$BJ$398*($BM$389+$I3))+$AP3*($BK$399+$BJ$399*($BM$389+$I3))+$AR3*($BK$401+$BJ$401*($BM$389+$I3))+$AS3*($BK$402+$BJ$402*($BM$389+$I3))+$AT3*($BK$403+$BJ$403*($BM$389+$I3))+$AU3*($BK$404+$BJ$404*($BM$389+$I3))+$AV3*($BK$405+$BJ$405*($BM$389+$I3))+$AW3*($BK$406+$BJ$406*($BM$389+$I3))+$AX3*($BK$407+$BJ$407*($BM$389+$I3))+$AY3*($BK$408+$BJ$408*($BM$389+$I3))+$AZ3*($BK$409+$BJ$409*($BM$389+$I3))+$BB3*($BK$411+$BJ$411*($BM$389+$I3))+$BC3*($BK$412+$BJ$412*($BM$389+$I3))+$BD3*($BK$413+$BJ$413*($BM$389+$I3))+$BF3*($BK$415+$BJ$415*($BM$389+$I3))+$BI3*($BK$416+$BJ$416*($BM$389+$I3)))/(SUM($AM3:$BJ3)-$AQ3-$BA3-$BE3-$BG3-$BH3-$BJ3)) -> -136.54296 | BL3: =IF($K3=$L3,$BK3,IF(OR($K3="graphite",$K3="vitreous carbon"),$BK$406+($BM$389+$I3)*$BJ$406,IF($K3="Pyrolytic Boron Nitride","PBN",IF(COUNTIF($BH$396:$BH$416,$K3)>0,VLOOKUP($K3,$BH$396:$BK$416,4,FALSE)+($BM$389+$I3)*VLOOKUP($K3,$BH$396:$BK$416,3,FALSE),IF(COUNTIF($L1:$L$238,$K3)>0,VLOOKUP($K3,$L1:$BK$238,52,FALSE),"idk"))))) -> -63.529672 | BM3: 13 | BN3: 7 | BO3: 1 | BP3: FLiBe | BQ3: ORNL | BR3: yes | BT3: 0 | DJ3: 0 | DK3: 0 | DM3: -13.7 | DN3: -31.2 | DO3: -0.27 | DT3: https://enispa.sharepoint.com/sites/Venicelaboratories-FLiNaKandFLiBecorrosion/Documenti%20condivisi/FLiNaK%20and%20FLiBe%20corrosion/3.%20Letteratura/Attività%202023/2015_Zheng_Corrosion%20of%20316%20stainless%20steel%20in%20high%20temperature%20molten%20Li2BeF4%20(FLiBe)%20salt.pdf | DU3: Composizione NOMINALE dei provini | DW3: =SUM(_2025_01_07T12_47_export3[[#This Row],[Ni_wt]:[H_wt]]) -> 100 | DY3: =SUM($AM3:BJ3) -> 100
A4: A0316 L SS2015Zheng | B4: 2 | C4: University of Wisconsin Madison | D4: 2020 | E4: Zheng | F4: A0 | G4: static | H4: 0 | I4: 700 | J4: 2000 | K4: 316 L SS | L4: 316 L SS | N4: 7980000 | O4: 10.025 | P4: 16.825 | Q4: 2.0115 | R4: =100-SUM(_2025_01_07T12_47_export3[[#This Row],[Ni_wt]:[Mo_wt]],_2025_01_07T12_47_export3[[#This Row],[W_wt]:[H_wt]]) -> 68.6109 | U4: 1.5305 | X4: 0.309 | Y4: 0.225 | Z4: 0.3795 | AC4: 0.031 | AD4: 0.0016 | AJ4: 0.051 | AM4: =100*(O4/BD$343)/($O4/$BD$343+$P4/$BD$344+$Q4/$BD$346+$R4/$BD$348+$S4/$BD$350+$T4/$BD$351+$U4/$BD$352+$V4/$BD$353+$W4/$BD$354+$X4/$BD$359+$Y4/$BD$360+$Z4/$BD$361+$AA4/$BD$362+$AB4/$BD$363+$AC4/$BD$364+$AD4/$BD$365+$AE4/$BD$366+$AF4/$BD$367+$AG4/$BD$369+$AH4/$BD$355+$AI4/$BD$356+$AJ4/$BD$357+$AK4/$BD$368+$AL4/$BD$358) -> 9.4263736 | AN4: =100*(P4/BD$344)/($O4/$BD$343+$P4/$BD$344+$Q4/$BD$346+$R4/$BD$348+$S4/$BD$350+$T4/$BD$351+$U4/$BD$352+$V4/$BD$353+$W4/$BD$354+$X4/$BD$359+$Y4/$BD$360+$Z4/$BD$361+$AA4/$BD$362+$AB4/$BD$363+$AC4/$BD$364+$AD4/$BD$365+$AE4/$BD$366+$AF4/$BD$367+$AG4/$BD$369+$AH4/$BD$355+$AI4/$BD$356+$AJ4/$BD$357+$AK4/$BD$368+$AL4/$BD$358) -> 17.855668 | AO4: =100*(Q4/BD$346)/($O4/$BD$343+$P4/$BD$344+$Q4/$BD$346+$R4/$BD$348+$S4/$BD$350+$T4/$BD$351+$U4/$BD$352+$V4/$BD$353+$W4/$BD$354+$X4/$BD$359+$Y4/$BD$360+$Z4/$BD$361+$AA4/$BD$362+$AB4/$BD$363+$AC4/$BD$364+$AD4/$BD$365+$AE4/$BD$366+$AF4/$BD$367+$AG4/$BD$369+$AH4/$BD$355+$AI4/$BD$356+$AJ4/$BD$357+$AK4/$BD$368+$AL4/$BD$358) -> 1.1567891 | AP4: =100*(R4/BD$348)/($O4/$BD$343+$P4/$BD$344+$Q4/$BD$346+$R4/$BD$348+$S4/$BD$350+$T4/$BD$351+$U4/$BD$352+$V4/$BD$353+$W4/$BD$354+$X4/$BD$359+$Y4/$BD$360+$Z4/$BD$361+$AA4/$BD$362+$AB4/$BD$363+$AC4/$BD$364+$AD4/$BD$365+$AE4/$BD$366+$AF4/$BD$367+$AG4/$BD$369+$AH4/$BD$355+$AI4/$BD$356+$AJ4/$BD$357+$AK4/$BD$368+$AL4/$BD$358) -> 67.794477 | AQ4: =100*(S4/BD$350)/($O4/$BD$343+$P4/$BD$344+$Q4/$BD$346+$R4/$BD$348+$S4/$BD$350+$T4/$BD$351+$U4/$BD$352+$V4/$BD$353+$W4/$BD$354+$X4/$BD$359+$Y4/$BD$360+$Z4/$BD$361+$AA4/$BD$362+$AB4/$BD$363+$AC4/$BD$364+$AD4/$BD$365+$AE4/$BD$366+$AF4/$BD$367+$AG4/$BD$369+$AH4/$BD$355+$AI4/$BD$356+$AJ4/$BD$357+$AK4/$BD$368+$AL4/$BD$358) -> 0 | AR4: =100*(T4/BD$351)/($O4/$BD$343+$P4/$BD$344+$Q4/$BD$346+$R4/$BD$348+$S4/$BD$350+$T4/$BD$351+$U4/$BD$352+$V4/$BD$353+$W4/$BD$354+$X4/$BD$359+$Y4/$BD$360+$Z4/$BD$361+$AA4/$BD$362+$AB4/$BD$363+$AC4/$BD$364+$AD4/$BD$365+$AE4/$BD$366+$AF4/$BD$367+$AG4/$BD$369+$AH4/$BD$355+$AI4/$BD$356+$AJ4/$BD$357+$AK4/$BD$368+$AL4/$BD$358) -> 0 | AS4: =100*(U4/BD$352)/($O4/$BD$343+$P4/$BD$344+$Q4/$BD$346+$R4/$BD$348+$S4/$BD$350+$T4/$BD$351+$U4/$BD$352+$V4/$BD$353+$W4/$BD$354+$X4/$BD$359+$Y4/$BD$360+$Z4/$BD$361+$AA4/$BD$362+$AB4/$BD$363+$AC4/$BD$364+$AD4/$BD$365+$AE4/$BD$366+$AF4/$BD$367+$AG4/$BD$369+$AH4/$BD$355+$AI4/$BD$356+$AJ4/$BD$357+$AK4/$BD$368+$AL4/$BD$358) -> 1.5373369 | AT4: =100*(V4/BD$353)/($O4/$BD$343+$P4/$BD$344+$Q4/$BD$346+$R4/$BD$348+$S4/$BD$350+$T4/$BD$351+$U4/$BD$352+$V4/$BD$353+$W4/$BD$354+$X4/$BD$359+$Y4/$BD$360+$Z4/$BD$361+$AA4/$BD$362+$AB4/$BD$363+$AC4/$BD$364+$AD4/$BD$365+$AE4/$BD$366+$AF4/$BD$367+$AG4/$BD$369+$AH4/$BD$355+$AI4/$BD$356+$AJ4/$BD$357+$AK4/$BD$368+$AL4/$BD$358) -> 0 | AU4: =100*(W4/BD$354)/($O4/$BD$343+$P4/$BD$344+$Q4/$BD$346+$R4/$BD$348+$S4/$BD$350+$T4/$BD$351+$U4/$BD$352+$V4/$BD$353+$W4/$BD$354+$X4/$BD$359+$Y4/$BD$360+$Z4/$BD$361+$AA4/$BD$362+$AB4/$BD$363+$AC4/$BD$364+$AD4/$BD$365+$AE4/$BD$366+$AF4/$BD$367+$AG4/$BD$369+$AH4/$BD$355+$AI4/$BD$356+$AJ4/$BD$357+$AK4/$BD$368+$AL4/$BD$358) -> 0 | AV4: =100*(X4/BD$359)/($O4/$BD$343+$P4/$BD$344+$Q4/$BD$346+$R4/$BD$348+$S4/$BD$350+$T4/$BD$351+$U4/$BD$352+$V4/$BD$353+$W4/$BD$354+$X4/$BD$359+$Y4/$BD$360+$Z4/$BD$361+$AA4/$BD$362+$AB4/$BD$363+$AC4/$BD$364+$AD4/$BD$365+$AE4/$BD$366+$AF4/$BD$367+$AG4/$BD$369+$AH4/$BD$355+$AI4/$BD$356+$AJ4/$BD$357+$AK4/$BD$368+$AL4/$BD$358) -> 0.6070593 | AW4: =100*(Y4/BD$360)/($O4/$BD$343+$P4/$BD$344+$Q4/$BD$346+$R4/$BD$348+$S4/$BD$350+$T4/$BD$351+$U4/$BD$352+$V4/$BD$353+$W4/$BD$354+$X4/$BD$359+$Y4/$BD$360+$Z4/$BD$361+$AA4/$BD$362+$AB4/$BD$363+$AC4/$BD$364+$AD4/$BD$365+$AE4/$BD$366+$AF4/$BD$367+$AG4/$BD$369+$AH4/$BD$355+$AI4/$BD$356+$AJ4/$BD$357+$AK4/$BD$368+$AL4/$BD$358) -> 1.0338651 | AX4: =100*(Z4/BD$361)/($O4/$BD$343+$P4/$BD$344+$Q4/$BD$346+$R4/$BD$348+$S4/$BD$350+$T4/$BD$351+$U4/$BD$352+$V4/$BD$353+$W4/$BD$354+$X4/$BD$359+$Y4/$BD$360+$Z4/$BD$361+$AA4/$BD$362+$AB4/$BD$363+$AC4/$BD$364+$AD4/$BD$365+$AE4/$BD$366+$AF4/$BD$367+$AG4/$BD$369+$AH4/$BD$355+$AI4/$BD$356+$AJ4/$BD$357+$AK4/$BD$368+$AL4/$BD$358) -> 0.32954946 | AY4: =100*(AA4/BD$362)/($O4/$BD$343+$P4/$BD$344+$Q4/$BD$346+$R4/$BD$348+$S4/$BD$350+$T4/$BD$351+$U4/$BD$352+$V4/$BD$353+$W4/$BD$354+$X4/$BD$359+$Y4/$BD$360+$Z4/$BD$361+$AA4/$BD$362+$AB4/$BD$363+$AC4/$BD$364+$AD4/$BD$365+$AE4/$BD$366+$AF4/$BD$367+$AG4/$BD$369+$AH4/$BD$355+$AI4/$BD$356+$AJ4/$BD$357+$AK4/$BD$368+$AL4/$BD$358) -> 0 | AZ4: =100*(AB4/BD$363)/($O4/$BD$343+$P4/$BD$344+$Q4/$BD$346+$R4/$BD$348+$S4/$BD$350+$T4/$BD$351+$U4/$BD$352+$V4/$BD$353+$W4/$BD$354+$X4/$BD$359+$Y4/$BD$360+$Z4/$BD$361+$AA4/$BD$362+$AB4/$BD$363+$AC4/$BD$364+$AD4/$BD$365+$AE4/$BD$366+$AF4/$BD$367+$AG4/$BD$369+$AH4/$BD$355+$AI4/$BD$356+$AJ4/$BD$357+$AK4/$BD$368+$AL4/$BD$358) -> 0 | BA4: =100*(AC4/BD$364)/($O4/$BD$343+$P4/$BD$344+$Q4/$BD$346+$R4/$BD$348+$S4/$BD$350+$T4/$BD$351+$U4/$BD$352+$V4/$BD$353+$W4/$BD$354+$X4/$BD$359+$Y4/$BD$360+$Z4/$BD$361+$AA4/$BD$362+$AB4/$BD$363+$AC4/$BD$364+$AD4/$BD$365+$AE4/$BD$366+$AF4/$BD$367+$AG4/$BD$369+$AH4/$BD$355+$AI4/$BD$356+$AJ4/$BD$357+$AK4/$BD$368+$AL4/$BD$358) -> 0.05523888 | BB4: =100*(AD4/BD$365)/($O4/$BD$343+$P4/$BD$344+$Q4/$BD$346+$R4/$BD$348+$S4/$BD$350+$T4/$BD$351+$U4/$BD$352+$V4/$BD$353+$W4/$BD$354+$X4/$BD$359+$Y4/$BD$360+$Z4/$BD$361+$AA4/$BD$362+$AB4/$BD$363+$AC4/$BD$364+$AD4/$BD$365+$AE4/$BD$366+$AF4/$BD$367+$AG4/$BD$369+$AH4/$BD$355+$AI4/$BD$356+$AJ4/$BD$357+$AK4/$BD$368+$AL4/$BD$358) -> 0.0027532484 | BC4: =100*(AE4/BD$366)/($O4/$BD$343+$P4/$BD$344+$Q4/$BD$346+$R4/$BD$348+$S4/$BD$350+$T4/$BD$351+$U4/$BD$352+$V4/$BD$353+$W4/$BD$354+$X4/$BD$359+$Y4/$BD$360+$Z4/$BD$361+$AA4/$BD$362+$AB4/$BD$363+$AC4/$BD$364+$AD4/$BD$365+$AE4/$BD$366+$AF4/$BD$367+$AG4/$BD$369+$AH4/$BD$355+$AI4/$BD$356+$AJ4/$BD$357+$AK4/$BD$368+$AL4/$BD$358) -> 0 | BD4: =100*(AF4/BD$367)/($O4/$BD$343+$P4/$BD$344+$Q4/$BD$346+$R4/$BD$348+$S4/$BD$350+$T4/$BD$351+$U4/$BD$352+$V4/$BD$353+$W4/$BD$354+$X4/$BD$359+$Y4/$BD$360+$Z4/$BD$361+$AA4/$BD$362+$AB4/$BD$363+$AC4/$BD$364+$AD4/$BD$365+$AE4/$BD$366+$AF4/$BD$367+$AG4/$BD$369+$AH4/$BD$355+$AI4/$BD$356+$AJ4/$BD$357+$AK4/$BD$368+$AL4/$BD$358) -> 0 | BE4: =100*(AG4/BD$369)/($O4/$BD$343+$P4/$BD$344+$Q4/$BD$346+$R4/$BD$348+$S4/$BD$350+$T4/$BD$351+$U4/$BD$352+$V4/$BD$353+$W4/$BD$354+$X4/$BD$359+$Y4/$BD$360+$Z4/$BD$361+$AA4/$BD$362+$AB4/$BD$363+$AC4/$BD$364+$AD4/$BD$365+$AE4/$BD$366+$AF4/$BD$367+$AG4/$BD$369+$AH4/$BD$355+$AI4/$BD$356+$AJ4/$BD$357+$AK4/$BD$368+$AL4/$BD$358) -> 0 | BF4: =100*(AH4/BD$355)/($O4/$BD$343+$P4/$BD$344+$Q4/$BD$346+$R4/$BD$348+$S4/$BD$350+$T4/$BD$351+$U4/$BD$352+$V4/$BD$353+$W4/$BD$354+$X4/$BD$359+$Y4/$BD$360+$Z4/$BD$361+$AA4/$BD$362+$AB4/$BD$363+$AC4/$BD$364+$AD4/$BD$365+$AE4/$BD$366+$AF4/$BD$367+$AG4/$BD$369+$AH4/$BD$355+$AI4/$BD$356+$AJ4/$BD$357+$AK4/$BD$368+$AL4/$BD$358) -> 0 | BG4: =100*(AI4/BD$356)/($O4/$BD$343+$P4/$BD$344+$Q4/$BD$346+$R4/$BD$348+$S4/$BD$350+$T4/$BD$351+$U4/$BD$352+$V4/$BD$353+$W4/$BD$354+$X4/$BD$359+$Y4/$BD$360+$Z4/$BD$361+$AA4/$BD$362+$AB4/$BD$363+$AC4/$BD$364+$AD4/$BD$365+$AE4/$BD$366+$AF4/$BD$367+$AG4/$BD$369+$AH4/$BD$355+$AI4/$BD$356+$AJ4/$BD$357+$AK4/$BD$368+$AL4/$BD$358) -> 0 | BH4: =100*(AJ4/BD$357)/($O4/$BD$343+$P4/$BD$344+$Q4/$BD$346+$R4/$BD$348+$S4/$BD$350+$T4/$BD$351+$U4/$BD$352+$V4/$BD$353+$W4/$BD$354+$X4/$BD$359+$Y4/$BD$360+$Z4/$BD$361+$AA4/$BD$362+$AB4/$BD$363+$AC4/$BD$364+$AD4/$BD$365+$AE4/$BD$366+$AF4/$BD$367+$AG4/$BD$369+$AH4/$BD$355+$AI4/$BD$356+$AJ4/$BD$357+$AK4/$BD$368+$AL4/$BD$358) -> 0.20088912 | BI4: =100*(AK4/BD$368)/($O4/$BD$343+$P4/$BD$344+$Q4/$BD$346+$R4/$BD$348+$S4/$BD$350+$T4/$BD$351+$U4/$BD$352+$V4/$BD$353+$W4/$BD$354+$X4/$BD$359+$Y4/$BD$360+$Z4/$BD$361+$AA4/$BD$362+$AB4/$BD$363+$AC4/$BD$364+$AD4/$BD$365+$AE4/$BD$366+$AF4/$BD$367+$AG4/$BD$369+$AH4/$BD$355+$AI4/$BD$356+$AJ4/$BD$357+$AK4/$BD$368+$AL4/$BD$358) -> 0 | BJ4: =100*(AL4/BD$358)/($O4/$BD$343+$P4/$BD$344+$Q4/$BD$346+$R4/$BD$348+$S4/$BD$350+$T4/$BD$351+$U4/$BD$352+$V4/$BD$353+$W4/$BD$354+$X4/$BD$359+$Y4/$BD$360+$Z4/$BD$361+$AA4/$BD$362+$AB4/$BD$363+$AC4/$BD$364+$AD4/$BD$365+$AE4/$BD$366+$AF4/$BD$367+$AG4/$BD$369+$AH4/$BD$355+$AI4/$BD$356+$AJ4/$BD$357+$AK4/$BD$368+$AL4/$BD$358) -> 0 | BK4: =(($AM4*($BK$396+$BJ$396*($BM$389+$I4))+$AN4*($BK$397+$BJ$397*($BM$389+$I4))+$AO4*($BK$398+$BJ$398*($BM$389+$I4))+$AP4*($BK$399+$BJ$399*($BM$389+$I4))+$AR4*($BK$401+$BJ$401*($BM$389+$I4))+$AS4*($BK$402+$BJ$402*($BM$389+$I4))+$AT4*($BK$403+$BJ$403*($BM$389+$I4))+$AU4*($BK$404+$BJ$404*($BM$389+$I4))+$AV4*($BK$405+$BJ$405*($BM$389+$I4))+$AW4*($BK$406+$BJ$406*($BM$389+$I4))+$AX4*($BK$407+$BJ$407*($BM$389+$I4))+$AY4*($BK$408+$BJ$408*($BM$389+$I4))+$AZ4*($BK$409+$BJ$409*($BM$389+$I4))+$BB4*($BK$411+$BJ$411*($BM$389+$I4))+$BC4*($BK$412+$BJ$412*($BM$389+$I4))+$BD4*($BK$413+$BJ$413*($BM$389+$I4))+$BF4*($BK$415+$BJ$415*($BM$389+$I4))+$BI4*($BK$416+$BJ$416*($BM$389+$I4)))/(SUM($AM4:$BJ4)-$AQ4-$BA4-$BE4-$BG4-$BH4-$BJ4)) -> -136.54296 | BL4: =IF($K4=$L4,$BK4,IF(OR($K4="graphite",$K4="vitreous carbon"),$BK$406+($BM$389+$I4)*$BJ$406,IF($K4="Pyrolytic Boron Nitride","PBN",IF(COUNTIF($BH$396:$BH$416,$K4)>0,VLOOKUP($K4,$BH$396:$BK$416,4,FALSE)+($BM$389+$I4)*VLOOKUP($K4,$BH$396:$BK$416,3,FALSE),IF(COUNTIF($L$2:$L3,$K4)>0,VLOOKUP($K4,$L$2:$BK3,52,FALSE),"idk"))))) -> -136.54296 | BM4: 13 | BN4: 7 | BO4: 1 | BP4: FLiBe | BQ4: ORNL | BR4: yes | BT4: 0 | DJ4: 0 | DK4: 0 | DM4: -10.7 | DN4: -17.1 | DO4: -0.35 | DT4: https://enispa.sharepoint.com/sites/Venicelaboratories-FLiNaKandFLiBecorrosion/Documenti%20condivisi/FLiNaK%20and%20FLiBe%20corrosion/3.%20Letteratura/Attività%202023/2015_Zheng_High%20Temperature%20Corrosion%20of%20Hastelloy%20N%20in%20Molten%20Li2BeF4%20(FLiBe)%20Salt.pdf | DU4: Composizione NOMINALE dei provini | DW4: =SUM(_2025_01_07T12_47_export3[[#This Row],[Ni_wt]:[H_wt]]) -> 100 | DY4: =SUM($AM4:BJ4) -> 100
A5: A0316 L SS2015Zheng | B5: 3 | C5: University of Wisconsin Madison | D5: 2021 | E5: Zheng | F5: A0 | G5: static | H5: 0 | I5: 700 | J5: 2000 | K5: graphite | L5: 316 L SS | N5: 7980000 | O5: 10.025 | P5: 16.825 | Q5: 2.0115 | R5: =100-SUM(_2025_01_07T12_47_export3[[#This Row],[Ni_wt]:[Mo_wt]],_2025_01_07T12_47_export3[[#This Row],[W_wt]:[H_wt]]) -> 68.6109 | U5: 1.5305 | X5: 0.309 | Y5: 0.225 | Z5: 0.3795 | AC5: 0.031 | AD5: 0.0016 | AJ5: 0.051 | AM5: =100*(O5/BD$343)/($O5/$BD$343+$P5/$BD$344+$Q5/$BD$346+$R5/$BD$348+$S5/$BD$350+$T5/$BD$351+$U5/$BD$352+$V5/$BD$353+$W5/$BD$354+$X5/$BD$359+$Y5/$BD$360+$Z5/$BD$361+$AA5/$BD$362+$AB5/$BD$363+$AC5/$BD$364+$AD5/$BD$365+$AE5/$BD$366+$AF5/$BD$367+$AG5/$BD$369+$AH5/$BD$355+$AI5/$BD$356+$AJ5/$BD$357+$AK5/$BD$368+$AL5/$BD$358) -> 9.4263736 | AN5: =100*(P5/BD$344)/($O5/$BD$343+$P5/$BD$344+$Q5/$BD$346+$R5/$BD$348+$S5/$BD$350+$T5/$BD$351+$U5/$BD$352+$V5/$BD$353+$W5/$BD$354+$X5/$BD$359+$Y5/$BD$360+$Z5/$BD$361+$AA5/$BD$362+$AB5/$BD$363+$AC5/$BD$364+$AD5/$BD$365+$AE5/$BD$366+$AF5/$BD$367+$AG5/$BD$369+$AH5/$BD$355+$AI5/$BD$356+$AJ5/$BD$357+$AK5/$BD$368+$AL5/$BD$358) -> 17.855668 | AO5: =100*(Q5/BD$346)/($O5/$BD$343+$P5/$BD$344+$Q5/$BD$346+$R5/$BD$348+$S5/$BD$350+$T5/$BD$351+$U5/$BD$352+$V5/$BD$353+$W5/$BD$354+$X5/$BD$359+$Y5/$BD$360+$Z5/$BD$361+$AA5/$BD$362+$AB5/$BD$363+$AC5/$BD$364+$AD5/$BD$365+$AE5/$BD$366+$AF5/$BD$367+$AG5/$BD$369+$AH5/$BD$355+$AI5/$BD$356+$AJ5/$BD$357+$AK5/$BD$368+$AL5/$BD$358) -> 1.1567891 | AP5: =100*(R5/BD$348)/($O5/$BD$343+$P5/$BD$344+$Q5/$BD$346+$R5/$BD$348+$S5/$BD$350+$T5/$BD$351+$U5/$BD$352+$V5/$BD$353+$W5/$BD$354+$X5/$BD$359+$Y5/$BD$360+$Z5/$BD$361+$AA5/$BD$362+$AB5/$BD$363+$AC5/$BD$364+$AD5/$BD$365+$AE5/$BD$366+$AF5/$BD$367+$AG5/$BD$369+$AH5/$BD$355+$AI5/$BD$356+$AJ5/$BD$357+$AK5/$BD$368+$AL5/$BD$358) -> 67.794477 | AQ5: =100*(S5/BD$350)/($O5/$BD$343+$P5/$BD$344+$Q5/$BD$346+$R5/$BD$348+$S5/$BD$350+$T5/$BD$351+$U5/$BD$352+$V5/$BD$353+$W5/$BD$354+$X5/$BD$359+$Y5/$BD$360+$Z5/$BD$361+$AA5/$BD$362+$AB5/$BD$363+$AC5/$BD$364+$AD5/$BD$365+$AE5/$BD$366+$AF5/$BD$367+$AG5/$BD$369+$AH5/$BD$355+$AI5/$BD$356+$AJ5/$BD$357+$AK5/$BD$368+$AL5/$BD$358) -> 0 | AR5: =100*(T5/BD$351)/($O5/$BD$343+$P5/$BD$344+$Q5/$BD$346+$R5/$BD$348+$S5/$BD$350+$T5/$BD$351+$U5/$BD$352+$V5/$BD$353+$W5/$BD$354+$X5/$BD$359+$Y5/$BD$360+$Z5/$BD$361+$AA5/$BD$362+$AB5/$BD$363+$AC5/$BD$364+$AD5/$BD$365+$AE5/$BD$366+$AF5/$BD$367+$AG5/$BD$369+$AH5/$BD$355+$AI5/$BD$356+$AJ5/$BD$357+$AK5/$BD$368+$AL5/$BD$358) -> 0 | AS5: =100*(U5/BD$352)/($O5/$BD$343+$P5/$BD$344+$Q5/$BD$346+$R5/$BD$348+$S5/$BD$350+$T5/$BD$351+$U5/$BD$352+$V5/$BD$353+$W5/$BD$354+$X5/$BD$359+$Y5/$BD$360+$Z5/$BD$361+$AA5/$BD$362+$AB5/$BD$363+$AC5/$BD$364+$AD5/$BD$365+$AE5/$BD$366+$AF5/$BD$367+$AG5/$BD$369+$AH5/$BD$355+$AI5/$BD$356+$AJ5/$BD$357+$AK5/$BD$368+$AL5/$BD$358) -> 1.5373369 | AT5: =100*(V5/BD$353)/($O5/$BD$343+$P5/$BD$344+$Q5/$BD$346+$R5/$BD$348+$S5/$BD$350+$T5/$BD$351+$U5/$BD$352+$V5/$BD$353+$W5/$BD$354+$X5/$BD$359+$Y5/$BD$360+$Z5/$BD$361+$AA5/$BD$362+$AB5/$BD$363+$AC5/$BD$364+$AD5/$BD$365+$AE5/$BD$366+$AF5/$BD$367+$AG5/$BD$369+$AH5/$BD$355+$AI5/$BD$356+$AJ5/$BD$357+$AK5/$BD$368+$AL5/$BD$358) -> 0 | AU5: =100*(W5/BD$354)/($O5/$BD$343+$P5/$BD$344+$Q5/$BD$346+$R5/$BD$348+$S5/$BD$350+$T5/$BD$351+$U5/$BD$352+$V5/$BD$353+$W5/$BD$354+$X5/$BD$359+$Y5/$BD$360+$Z5/$BD$361+$AA5/$BD$362+$AB5/$BD$363+$AC5/$BD$364+$AD5/$BD$365+$AE5/$BD$366+$AF5/$BD$367+$AG5/$BD$369+$AH5/$BD$355+$AI5/$BD$356+$AJ5/$BD$357+$AK5/$BD$368+$AL5/$BD$358) -> 0 | AV5: =100*(X5/BD$359)/($O5/$BD$343+$P5/$BD$344+$Q5/$BD$346+$R5/$BD$348+$S5/$BD$350+$T5/$BD$351+$U5/$BD$352+$V5/$BD$353+$W5/$BD$354+$X5/$BD$359+$Y5/$BD$360+$Z5/$BD$361+$AA5/$BD$362+$AB5/$BD$363+$AC5/$BD$364+$AD5/$BD$365+$AE5/$BD$366+$AF5/$BD$367+$AG5/$BD$369+$AH5/$BD$355+$AI5/$BD$356+$AJ5/$BD$357+$AK5/$BD$368+$AL5/$BD$358) -> 0.6070593 | AW5: =100*(Y5/BD$360)/($O5/$BD$343+$P5/$BD$344+$Q5/$BD$346+$R5/$BD$348+$S5/$BD$350+$T5/$BD$351+$U5/$BD$352+$V5/$BD$353+$W5/$BD$354+$X5/$BD$359+$Y5/$BD$360+$Z5/$BD$361+$AA5/$BD$362+$AB5/$BD$363+$AC5/$BD$364+$AD5/$BD$365+$AE5/$BD$366+$AF5/$BD$367+$AG5/$BD$369+$AH5/$BD$355+$AI5/$BD$356+$AJ5/$BD$357+$AK5/$BD$368+$AL5/$BD$358) -> 1.0338651 | AX5: =100*(Z5/BD$361)/($O5/$BD$343+$P5/$BD$344+$Q5/$BD$346+$R5/$BD$348+$S5/$BD$350+$T5/$BD$351+$U5/$BD$352+$V5/$BD$353+$W5/$BD$354+$X5/$BD$359+$Y5/$BD$360+$Z5/$BD$361+$AA5/$BD$362+$AB5/$BD$363+$AC5/$BD$364+$AD5/$BD$365+$AE5/$BD$366+$AF5/$BD$367+$AG5/$BD$369+$AH5/$BD$355+$AI5/$BD$356+$AJ5/$BD$357+$AK5/$BD$368+$AL5/$BD$358) -> 0.32954946 | AY5: =100*(AA5/BD$362)/($O5/$BD$343+$P5/$BD$344+$Q5/$BD$346+$R5/$BD$348+$S5/$BD$350+$T5/$BD$351+$U5/$BD$352+$V5/$BD$353+$W5/$BD$354+$X5/$BD$359+$Y5/$BD$360+$Z5/$BD$361+$AA5/$BD$362+$AB5/$BD$363+$AC5/$BD$364+$AD5/$BD$365+$AE5/$BD$366+$AF5/$BD$367+$AG5/$BD$369+$AH5/$BD$355+$AI5/$BD$356+$AJ5/$BD$357+$AK5/$BD$368+$AL5/$BD$358) -> 0 | AZ5: =100*(AB5/BD$363)/($O5/$BD$343+$P5/$BD$344+$Q5/$BD$346+$R5/$BD$348+$S5/$BD$350+$T5/$BD$351+$U5/$BD$352+$V5/$BD$353+$W5/$BD$354+$X5/$BD$359+$Y5/$BD$360+$Z5/$BD$361+$AA5/$BD$362+$AB5/$BD$363+$AC5/$BD$364+$AD5/$BD$365+$AE5/$BD$366+$AF5/$BD$367+$AG5/$BD$369+$AH5/$BD$355+$AI5/$BD$356+$AJ5/$BD$357+$AK5/$BD$368+$AL5/$BD$358) -> 0 | BA5: =100*(AC5/BD$364)/($O5/$BD$343+$P5/$BD$344+$Q5/$BD$346+$R5/$BD$348+$S5/$BD$350+$T5/$BD$351+$U5/$BD$352+$V5/$BD$353+$W5/$BD$354+$X5/$BD$359+$Y5/$BD$360+$Z5/$BD$361+$AA5/$BD$362+$AB5/$BD$363+$AC5/$BD$364+$AD5/$BD$365+$AE5/$BD$366+$AF5/$BD$367+$AG5/$BD$369+$AH5/$BD$355+$AI5/$BD$356+$AJ5/$BD$357+$AK5/$BD$368+$AL5/$BD$358) -> 0.05523888 | BB5: =100*(AD5/BD$365)/($O5/$BD$343+$P5/$BD$344+$Q5/$BD$346+$R5/$BD$348+$S5/$BD$350+$T5/$BD$351+$U5/$BD$352+$V5/$BD$353+$W5/$BD$354+$X5/$BD$359+$Y5/$BD$360+$Z5/$BD$361+$AA5/$BD$362+$AB5/$BD$363+$AC5/$BD$364+$AD5/$BD$365+$AE5/$BD$366+$AF5/$BD$367+$AG5/$BD$369+$AH5/$BD$355+$AI5/$BD$356+$AJ5/$BD$357+$AK5/$BD$368+$AL5/$BD$358) -> 0.0027532484 | BC5: =100*(AE5/BD$366)/($O5/$BD$343+$P5/$BD$344+$Q5/$BD$346+$R5/$BD$348+$S5/$BD$350+$T5/$BD$351+$U5/$BD$352+$V5/$BD$353+$W5/$BD$354+$X5/$BD$359+$Y5/$BD$360+$Z5/$BD$361+$AA5/$BD$362+$AB5/$BD$363+$AC5/$BD$364+$AD5/$BD$365+$AE5/$BD$366+$AF5/$BD$367+$AG5/$BD$369+$AH5/$BD$355+$AI5/$BD$356+$AJ5/$BD$357+$AK5/$BD$368+$AL5/$BD$358) -> 0 | BD5: =100*(AF5/BD$367)/($O5/$BD$343+$P5/$BD$344+$Q5/$BD$346+$R5/$BD$348+$S5/$BD$350+$T5/$BD$351+$U5/$BD$352+$V5/$BD$353+$W5/$BD$354+$X5/$BD$359+$Y5/$BD$360+$Z5/$BD$361+$AA5/$BD$362+$AB5/$BD$363+$AC5/$BD$364+$AD5/$BD$365+$AE5/$BD$366+$AF5/$BD$367+$AG5/$BD$369+$AH5/$BD$355+$AI5/$BD$356+$AJ5/$BD$357+$AK5/$BD$368+$AL5/$BD$358) -> 0 | BE5: =100*(AG5/BD$369)/($O5/$BD$343+$P5/$BD$344+$Q5/$BD$346+$R5/$BD$348+$S5/$BD$350+$T5/$BD$351+$U5/$BD$352+$V5/$BD$353+$W5/$BD$354+$X5/$BD$359+$Y5/$BD$360+$Z5/$BD$361+$AA5/$BD$362+$AB5/$BD$363+$AC5/$BD$364+$AD5/$BD$365+$AE5/$BD$366+$AF5/$BD$367+$AG5/$BD$369+$AH5/$BD$355+$AI5/$BD$356+$AJ5/$BD$357+$AK5/$BD$368+$AL5/$BD$358) -> 0 | BF5: =100*(AH5/BD$355)/($O5/$BD$343+$P5/$BD$344+$Q5/$BD$346+$R5/$BD$348+$S5/$BD$350+$T5/$BD$351+$U5/$BD$352+$V5/$BD$353+$W5/$BD$354+$X5/$BD$359+$Y5/$BD$360+$Z5/$BD$361+$AA5/$BD$362+$AB5/$BD$363+$AC5/$BD$364+$AD5/$BD$365+$AE5/$BD$366+$AF5/$BD$367+$AG5/$BD$369+$AH5/$BD$355+$AI5/$BD$356+$AJ5/$BD$357+$AK5/$BD$368+$AL5/$BD$358) -> 0 | BG5: =100*(AI5/BD$356)/($O5/$BD$343+$P5/$BD$344+$Q5/$BD$346+$R5/$BD$348+$S5/$BD$350+$T5/$BD$351+$U5/$BD$352+$V5/$BD$353+$W5/$BD$354+$X5/$BD$359+$Y5/$BD$360+$Z5/$BD$361+$AA5/$BD$362+$AB5/$BD$363+$AC5/$BD$364+$AD5/$BD$365+$AE5/$BD$366+$AF5/$BD$367+$AG5/$BD$369+$AH5/$BD$355+$AI5/$BD$356+$AJ5/$BD$357+$AK5/$BD$368+$AL5/$BD$358) -> 0 | BH5: =100*(AJ5/BD$357)/($O5/$BD$343+$P5/$BD$344+$Q5/$BD$346+$R5/$BD$348+$S5/$BD$350+$T5/$BD$351+$U5/$BD$352+$V5/$BD$353+$W5/$BD$354+$X5/$BD$359+$Y5/$BD$360+$Z5/$BD$361+$AA5/$BD$362+$AB5/$BD$363+$AC5/$BD$364+$AD5/$BD$365+$AE5/$BD$366+$AF5/$BD$367+$AG5/$BD$369+$AH5/$BD$355+$AI5/$BD$356+$AJ5/$BD$357+$AK5/$BD$368+$AL5/$BD$358) -> 0.20088912 | BI5: =100*(AK5/BD$368)/($O5/$BD$343+$P5/$BD$344+$Q5/$BD$346+$R5/$BD$348+$S5/$BD$350+$T5/$BD$351+$U5/$BD$352+$V5/$BD$353+$W5/$BD$354+$X5/$BD$359+$Y5/$BD$360+$Z5/$BD$361+$AA5/$BD$362+$AB5/$BD$363+$AC5/$BD$364+$AD5/$BD$365+$AE5/$BD$366+$AF5/$BD$367+$AG5/$BD$369+$AH5/$BD$355+$AI5/$BD$356+$AJ5/$BD$357+$AK5/$BD$368+$AL5/$BD$358) -> 0 | BJ5: =100*(AL5/BD$358)/($O5/$BD$343+$P5/$BD$344+$Q5/$BD$346+$R5/$BD$348+$S5/$BD$350+$T5/$BD$351+$U5/$BD$352+$V5/$BD$353+$W5/$BD$354+$X5/$BD$359+$Y5/$BD$360+$Z5/$BD$361+$AA5/$BD$362+$AB5/$BD$363+$AC5/$BD$364+$AD5/$BD$365+$AE5/$BD$366+$AF5/$BD$367+$AG5/$BD$369+$AH5/$BD$355+$AI5/$BD$356+$AJ5/$BD$357+$AK5/$BD$368+$AL5/$BD$358) -> 0 | BK5: =(($AM5*($BK$396+$BJ$396*($BM$389+$I5))+$AN5*($BK$397+$BJ$397*($BM$389+$I5))+$AO5*($BK$398+$BJ$398*($BM$389+$I5))+$AP5*($BK$399+$BJ$399*($BM$389+$I5))+$AR5*($BK$401+$BJ$401*($BM$389+$I5))+$AS5*($BK$402+$BJ$402*($BM$389+$I5))+$AT5*($BK$403+$BJ$403*($BM$389+$I5))+$AU5*($BK$404+$BJ$404*($BM$389+$I5))+$AV5*($BK$405+$BJ$405*($BM$389+$I5))+$AW5*($BK$406+$BJ$406*($BM$389+$I5))+$AX5*($BK$407+$BJ$407*($BM$389+$I5))+$AY5*($BK$408+$BJ$408*($BM$389+$I5))+$AZ5*($BK$409+$BJ$409*($BM$389+$I5))+$BB5*($BK$411+$BJ$411*($BM$389+$I5))+$BC5*($BK$412+$BJ$412*($BM$389+$I5))+$BD5*($BK$413+$BJ$413*($BM$389+$I5))+$BF5*($BK$415+$BJ$415*($BM$389+$I5))+$BI5*($BK$416+$BJ$416*($BM$389+$I5)))/(SUM($AM5:$BJ5)-$AQ5-$BA5-$BE5-$BG5-$BH5-$BJ5)) -> -136.54296 | BL5: =IF($K5=$L5,$BK5,IF(OR($K5="graphite",$K5="vitreous carbon"),$BK$406+($BM$389+$I5)*$BJ$406,IF($K5="Pyrolytic Boron Nitride","PBN",IF(COUNTIF($BH$396:$BH$416,$K5)>0,VLOOKUP($K5,$BH$396:$BK$416,4,FALSE)+($BM$389+$I5)*VLOOKUP($K5,$BH$396:$BK$416,3,FALSE),IF(COUNTIF($L$2:$L4,$K5)>0,VLOOKUP($K5,$L$2:$BK4,52,FALSE),"idk"))))) -> -63.529672 | BM5: 13 | BN5: 7 | BO5: 1 | BP5: FLiBe | BQ5: ORNL | BR5: yes | BT5: 0 | DJ5: 0 | DK5: 0 | DM5: -19.4 | DN5: -31.2 | DO5: -0.41 | DT5: https://enispa.sharepoint.com/sites/Venicelaboratories-FLiNaKandFLiBecorrosion/Documenti%20condivisi/FLiNaK%20and%20FLiBe%20corrosion/3.%20Letteratura/Attività%202023/2018_Zheng-Sridharan_Article_CorrosionOfStructuralAlloysInH.pdf | DU5: Composizione NOMINALE dei provini | DW5: =SUM(_2025_01_07T12_47_export3[[#This Row],[Ni_wt]:[H_wt]]) -> 100 | DY5: =SUM($AM5:BJ5) -> 100
